<?xml version="1.0"?>
<robot name="CPRMover6">
	<!-- URDF file for the Commonplace Robotics Mover4 robot arm -->
	<!-- Version 1.1 from Oct. 04th, 2016. -->
	<!-- Used for fixing robot to Gazebo 'base_link' -->
	<link name="world"/>
	<joint name="fixed" type="fixed">
		<parent link="world"/>
		<child link="base_link"/>
	</joint>
    
	<link name="base_link">
		<visual>
			<origin rpy="0 0 0" xyz="0 0 0"/>
			<geometry>
				<mesh filename="package://mover6_description/meshes/Joint0.stl"  scale="0.001 0.001 0.001"/>
			</geometry>
		</visual>
		<collision>
			<origin xyz="0 0 0" rpy="0 0 0" />
			<geometry>
				<mesh filename="package://mover6_description/meshes/Joint0Coll.dae" scale="0.001 0.001 0.001"/>
			</geometry>
		</collision>
	</link>

	<link name="link1">
		<visual>
			<origin rpy="0 0 0" xyz="0 0 0"/>
			<geometry>
				<mesh filename="package://mover6_description/meshes/Joint1.dae"  scale="0.001 0.001 0.001"/>
			</geometry>
		</visual>
		<collision>
			<origin xyz="0 0 0" rpy="0 0 0" />
			<geometry>
				<mesh filename="package://mover6_description/meshes/Joint1Coll.dae" scale="0.001 0.001 0.001"/>
			</geometry>
		</collision>
	</link>

	<link name="link2">
		<visual>
			<origin rpy="0 0 0" xyz="0 0 0"/>
			<geometry>
				<mesh filename="package://mover6_description/meshes/Joint2.dae"  scale="0.001 0.001 0.001"/>
			</geometry>
		</visual>
		<collision>
			<origin xyz="0 0 0" rpy="0 0 0" />
			<geometry>
				<mesh filename="package://mover6_description/meshes/Joint2Coll.dae" scale="0.001 0.001 0.001"/>
			</geometry>
		</collision>
	</link>

	<link name="link3">
		<visual>
			<origin rpy="0 0 0" xyz="0 0 0"/>
			<geometry>
				<mesh filename="package://mover6_description/meshes/Joint3.dae"  scale="0.001 0.001 0.001"/>
			</geometry>
		</visual>
		<collision>
			<origin xyz="0 0 0" rpy="0 0 0" />
			<geometry>
				<mesh filename="package://mover6_description/meshes/Joint3Coll.dae" scale="0.001 0.001 0.001"/>
			</geometry>
		</collision>
	</link>

	<link name="link4">
		<visual>
			<origin rpy="0 0 0" xyz="0 0 0"/>
			<geometry>
				<mesh filename="package://mover6_description/meshes/Joint4.dae"  scale="0.001 0.001 0.001"/>
			</geometry>
		</visual>
		<collision>
			<origin xyz="0 0 0" rpy="0 0 0" />
			<geometry>
				<mesh filename="package://mover6_description/meshes/Joint4Coll.dae" scale="0.001 0.001 0.001"/>
			</geometry>
		</collision>
	</link>

	<link name="link5">
		<visual>
			<origin rpy="0 0 0" xyz="0 0 0"/>
			<geometry>
				<mesh filename="package://mover6_description/meshes/Joint5.dae"  scale="0.001 0.001 0.001"/>
			</geometry>
		</visual>
		<collision>
			<origin xyz="0 0 0" rpy="0 0 0" />
			<geometry>
				<mesh filename="package://mover6_description/meshes/Joint5Coll.dae" scale="0.001 0.001 0.001"/>
			</geometry>
		</collision>
	</link>

	<link name="link6">
		<visual>
			<origin rpy="0 0 0" xyz="0 0 0"/>
			<geometry>
				<mesh filename="package://mover6_description/meshes/Joint6.dae"  scale="0.001 0.001 0.001"/>
			</geometry>
		</visual>
		<collision>
			<origin xyz="0 0 0" rpy="0 0 0" />
			<geometry>
				<mesh filename="package://mover6_description/meshes/Joint6Coll.dae" scale="0.001 0.001 0.001"/>
			</geometry>
		</collision>
	</link>


	<joint name="joint1" type="revolute">
		<axis xyz="0 0 -1"/>
		<parent link="base_link"/>
		<child link="link1"/>
		<origin rpy="0 0 0" xyz="0 0 0.130"/>
		<limit lower="-2.27" upper="2.27" effort="100" velocity="30"/>
	</joint>

	<joint name="joint2" type="revolute">
		<axis xyz="0 1 0"/>
		<parent link="link1"/>
		<child link="link2"/>
		<origin rpy="0 0 0" xyz="0 0 0.0625"/>
		<limit lower="-0.87" upper="1.05" effort="100" velocity="30"/>
	</joint>

	<joint name="joint3" type="revolute">
		<axis xyz="0 1 0"/>
		<parent link="link2"/>
		<child link="link3"/>
		<origin rpy="0 1.57079632679 0" xyz="0 0 0.190"/>
		<limit lower="-1.92" upper="1.31" effort="100" velocity="30"/>
	</joint>

	<joint name="joint4" type="revolute">
		<axis xyz="0 0 1"/>
		<parent link="link3"/>
		<child link="link4"/>
		<origin rpy="0 0 0" xyz="-0.06 0 0"/>
		<limit lower="-2.44" upper="2.44" effort="100" velocity="30"/>
	</joint>

	<joint name="joint5" type="revolute">
		<axis xyz="0 1 0"/>
		<parent link="link4"/>
		<child link="link5"/>
		<origin rpy="0 0 0" xyz="0 0 0.290"/>
		<limit lower="-1.22" upper="1.05" effort="100" velocity="40"/>
	</joint>

	<joint name="joint6" type="revolute">
		<axis xyz="0 0 1"/>
		<parent link="link5"/>
		<child link="link6"/>
		<origin rpy="0 0 0" xyz="0 0 0.055"/>
		<limit lower="-2.09" upper="2.09" effort="100" velocity="100"/>
	</joint>
</robot>
